Workbook

Sheet Dashboard
A1: Infinity Training Syllabus
A2: Series-wise master plan: finish a topic once, at infinity depth, and never redo it. Mark Status as you go — this page counts everything live. The website's Syllabus page reads this same file.
A4: Track | B4: Topics | C4: Est. days | D4: Done | E4: Remaining | F4: % complete
A5: DSA | B5: 75 | C5: 128 | D5: =COUNTIF('DSA'!E:E,"Done") | E5: =B5-D5 | F5: =IF(B5=0,0,D5/B5)
A6: OS | B6: 27 | C6: 30 | D6: =COUNTIF('OS'!E:E,"Done") | E6: =B6-D6 | F6: =IF(B6=0,0,D6/B6)
A7: DBMS | B7: 24 | C7: 27 | D7: =COUNTIF('DBMS'!E:E,"Done") | E7: =B7-D7 | F7: =IF(B7=0,0,D7/B7)
A8: Networks | B8: 20 | C8: 22 | D8: =COUNTIF('Networks'!E:E,"Done") | E8: =B8-D8 | F8: =IF(B8=0,0,D8/B8)
A9: Linux | B9: 13 | C9: 13 | D9: =COUNTIF('Linux'!E:E,"Done") | E9: =B9-D9 | F9: =IF(B9=0,0,D9/B9)
A10: Frontend-TS-React | B10: 27 | C10: 47 | D10: =COUNTIF('Frontend-TS-React'!E:E,"Done") | E10: =B10-D10 | F10: =IF(B10=0,0,D10/B10)
A11: Backend-Node-Python | B11: 28 | C11: 40 | D11: =COUNTIF('Backend-Node-Python'!E:E,"Done") | E11: =B11-D11 | F11: =IF(B11=0,0,D11/B11)
A12: PostgreSQL | B12: 24 | C12: 28 | D12: =COUNTIF('PostgreSQL'!E:E,"Done") | E12: =B12-D12 | F12: =IF(B12=0,0,D12/B12)
A13: System-Design | B13: 24 | C13: 31 | D13: =COUNTIF('System-Design'!E:E,"Done") | E13: =B13-D13 | F13: =IF(B13=0,0,D13/B13)
A14: Security | B14: 14 | C14: 16 | D14: =COUNTIF('Security'!E:E,"Done") | E14: =B14-D14 | F14: =IF(B14=0,0,D14/B14)
A15: AI-Integration | B15: 25 | C15: 30 | D15: =COUNTIF('AI-Integration'!E:E,"Done") | E15: =B15-D15 | F15: =IF(B15=0,0,D15/B15)
A16: DevOps | B16: 24 | C16: 25 | D16: =COUNTIF('DevOps'!E:E,"Done") | E16: =B16-D16 | F16: =IF(B16=0,0,D16/B16)
A17: Behavioral-Projects | B17: 16 | C17: 16 | D17: =COUNTIF('Behavioral-Projects'!E:E,"Done") | E17: =B17-D17 | F17: =IF(B17=0,0,D17/B17)
A18: Open-Source-Zulip | B18: 12 | C18: 37 | D18: =COUNTIF('Open-Source-Zulip'!E:E,"Done") | E18: =B18-D18 | F18: =IF(B18=0,0,D18/B18)
A19: TOTAL | B19: =SUM(B5:B18) | C19: =SUM(C5:C18) | D19: =SUM(D5:D18) | E19: =SUM(E5:E18) | F19: =IF(B19=0,0,D19/B19)

Sheet DSA
A1: # | B1: Topic | C1: Subtopics / What to learn | D1: Day activity | E1: Status | F1: Est. days | G1: Done when | H1: Why it matters | I1: Depends on
A2: 1 | B2: Arrays & strings — timed diagnostic | C2: Kadane, rotation, product-except-self, in-place ops, string parsing | D2: Timed set: 4 mediums in 90 min, think aloud in English; log every stall in the error log | E2: Done | F2: 1 | G2: All 4 solved inside 90 min; stated O(n)/O(1) trade-offs per problem; explained the approach aloud in English before coding; handled edge cases (empty input, single element, duplicates, overflow, all-negative) without hints | H2: STEP interviews open with array/string warm-ups — these must fall in under 20 min while talking
A3: 2 | B3: Two pointers — timed diagnostic | C3: Opposite ends, fast/slow, 3Sum family, Dutch national flag, sorted-array pairs | D3: Timed set: 4 mediums in 90 min, think aloud; log stalls | E3: Not started | F3: 1 | G3: All 4 solved inside 90 min; can prove why the pointer move is safe for each; explained the approach aloud in English before coding; edge cases (empty input, single element, duplicates, overflow, all-negative) covered | H3: Two-pointer correctness arguments ('why can we discard this side?') are exactly what interviewers probe | I3: 1
A4: 3 | B4: Sliding window — timed diagnostic | C4: Fixed window, variable window, longest substring without repeat, max-sum subarray K | D4: Timed set: 4 mediums in 90 min, think aloud; log stalls | E4: Not started | F4: 1 | G4: All 4 solved inside 90 min; states the window invariant in one sentence per problem; explained the approach aloud in English before coding; edge cases (empty input, single element, duplicates, overflow, all-negative) covered | H4: The window invariant is the whole interview answer — if you can state it, the code writes itself | I4: 2
A5: 4 | B5: Hash maps — timed diagnostic | C5: Frequency maps, two-sum family, group anagrams, prefix-sum + map combos | D5: Timed set: 4 mediums in 90 min, think aloud; log stalls | E5: Not started | F5: 1 | G5: All 4 solved inside 90 min; justifies hash vs sort trade-off per problem; explained the approach aloud in English before coding; edge cases (empty input, single element, duplicates, overflow, all-negative) covered | H5: Hash-map design questions are free marks — but only if the trade-off reasoning is instant | I5: 3
A6: 5 | B6: Prefix sums — timed diagnostic | C6: Prefix array, difference array, subarray-sum-K, range-sum queries | D6: Timed set: 3 mediums in 75 min, think aloud; log stalls | E6: Not started | F6: 1 | G6: All 3 solved inside 75 min; derives the prefix relation on paper once; explained the approach aloud in English before coding; edge cases (empty input, single element, duplicates, overflow, all-negative) covered | H6: Prefix sums are the quiet prerequisite for half of DP and range problems later | I6: 4
A7: 6 | B7: Recursion mastery | C7: Recursion-tree drawing, base/inductive-case discipline, tail recursion, recursion-to-iteration, stack depth limits | D7: Solve 2 mediums (e.g. pow(x,n), kth symbol in grammar); draw the recursion tree for each on paper; convert one solution to iterative | E7: Not started | F7: 2 | G7: Can draw the recursion tree and write the T(n) recurrence for any recursive solution; converts recursion to iteration; justifies the base case aloud; states stack-depth limits; edge cases (empty input, single element, duplicates, overflow, all-negative) covered | H7: Every backtracking, tree, and DFS solution downstream is recursion — weak recursion poisons everything after it | I7: 5
A8: 7 | B8: Backtracking core patterns | C8: Choose/explore/unchoose template, subsets, permutations, combinations, dedup via sorting | D8: Learn the template cold; solve 3 mediums (subsets, permutations II, combination sum) | E8: Not started | F8: 2 | G8: Writes the template from memory; states state/choices/goal triple before coding each; proves the dedup logic; explained the approach aloud in English before coding; complexity (nodes x work per node) analyzed | H8: Interviewers don't want the code — they want the state/choice/goal framing. This is the backtracking interview | I8: 6
A9: 8 | B9: Backtracking hard I — constraint pruning | C9: N-Queens, Sudoku solver, word search; pruning with constraint sets | D9: Solve 1 hard + 1 medium; for each, name the constraint set that prunes the search and estimate pruned vs raw node count | E9: Not started | F9: 2 | G9: Both solved; can quantify pruning (raw vs pruned search space); explains constraint choice aloud; edge cases (empty input, single element, duplicates, overflow, all-negative) covered | H9: Hard backtracking is won or lost on pruning — interviewers ask 'how would you make this faster?' and this is the answer | I9: 7
A10: 9 | B10: Backtracking hard II | C10: Palindrome partitioning, expression add operators, remove invalid parentheses | D10: Solve 2 hards; write the state/choice/goals triple on paper before touching the keyboard | E10: Not started | F10: 2 | G10: Both solved; triple written before coding each time; complexity analyzed including dedup cost; explained the approach aloud in English before coding | H10: These are the hards that separate 'knows backtracking' from 'owns backtracking' in interviews | I10: 8
A11: 10 | B11: Backtracking speed drill | C11: Mixed set across recursion + backtracking topics | D11: Timed: 3 mediums in 75 min, think aloud; then re-solve the slowest one targeting under 20 min | E11: Not started | F11: 1 | G11: All 3 inside 75 min; slowest re-solved under 20 min; error log updated with the stall cause | H11: Speed is the bottleneck — this drill converts knowledge into interview-time performance | I11: 9
A12: 11 | B12: Stacks consolidation | C12: Monotonic increasing/decreasing stack, next-greater-element family, stock span | D12: Solve 2 mediums cold (no notes) + largest rectangle in histogram from scratch — consolidation of his recent grind | E12: Not started | F12: 1 | G12: All 3 solved without reference; states the monotonic invariant in one sentence per problem; explained the approach aloud in English before coding; edge cases (empty input, single element, duplicates, overflow, all-negative) covered | H12: He's been grinding stacks for 2 weeks — this locks it in permanently so it never needs revisiting | I12: 10
A13: 12 | B13: Hard stack problems | C13: Trapping rain water (stack view), maximal rectangle, asteroid collision, decode string | D13: Solve 2 hards; for each, explain why the stack invariant holds — aloud, before coding | E13: Not started | F13: 2 | G13: Both hards solved; invariant proved aloud for each; O(n) time / O(n) space justified; edge cases (empty input, single element, duplicates, overflow, all-negative) covered | H13: Stack hards test invariant thinking — the same muscle used in advanced DP and sweep-line later | I13: 11
A14: 13 | B14: Stack/queue design problems | C14: Min stack, implement queue with stacks, implement stack with queues, circular deque | D14: Implement 3 from scratch with amortized O(1) analysis written out for each operation | E14: Not started | F14: 2 | G14: All 3 implemented; amortized analysis written and defensible; explained the approach aloud in English before coding; edge cases (empty input, single element, duplicates, overflow, all-negative) covered | H14: Design-with-constraints problems are classic STEP/OA questions — amortized analysis is the interview differentiator | I14: 12
... A76: 75 | B76: Weak-spot revisit & sign-off | C76: Everything flagged in the error log across the arc | D76: Re-solve every error-log problem that once took 2+ attempts; the topic is done only when the log is empty | E76: Not started | F76: 3 | G76: Error log empty; every previously-failed problem now solved cleanly with explanation aloud; complexity + edge cases automatic | H76: Infinity-depth means never redoing: the arc ends when there is nothing left he cannot do | I76: 74

Sheet OS
A1: # | B1: Topic | C1: Subtopics / What to learn | D1: Day activity | E1: Status | F1: Est. days | G1: Done when | H1: Why it matters | I1: Depends on
A2: 1 | B2: What is an operating system | C2: What the OS manages (CPU, memory, devices); kernel vs user space; system calls; why programs can't touch hardware directly | D2: Learn (45 min): OS as resource manager + kernel/user mode + 3 real syscalls (read, write, fork). Quiz (15 min): 5 questions — define kernel, why two modes exist, name 2 OS-managed resources. | E2: Done | F2: 1 | G2: Can explain 'what is an OS' simply AND answer: what is a system call, why two CPU modes exist, what happens if a program touches hardware directly. | H2: Every OS interview starts here; 'what happens when you run a program' is the #1 opener.
A3: 2 | B3: How a program becomes a process | C3: Compilation to binary; the loader; address space layout: code, data, heap, stack; what 'running' means | D3: Learn (45): loader + memory layout diagram. Quiz (15): label a blank memory diagram; explain stack vs heap. | E3: Done | F3: 1 | G3: Can draw a process's memory layout from memory and explain what lives in each region and what the loader does. | H3: 'Draw process memory layout' is asked constantly; foundation for virtual memory. | I3: 1
A4: 3 | B4: Processes vs threads | C4: Definitions; PCB vs thread control block; shared vs isolated memory; real examples (Chrome processes, web-server threads) | D4: Learn (45): definitions + 2 real examples each. Quiz (15): 'why not always threads?' + one-sentence definitions. | E4: Done | F4: 1 | G4: Can define both in one sentence each, give 2 real-world examples of each, and answer 'why not always threads?' (crash isolation). | H4: 'Process vs thread' is a top-5 OS interview question. | I4: 2
A5: 4 | B5: Process lifecycle and states | C5: New, ready, running, waiting, terminated; PCB contents; state-transition diagram | D5: Learn (45): 5-state diagram + PCB fields. Quiz (15): redraw the diagram blank; list 5 PCB fields. | E5: Not started | F5: 1 | G5: Can draw the 5-state diagram from memory, explain what triggers each transition, and list 5 PCB fields. | H5: Interviewers love 'draw the process state diagram'. | I5: 3
A6: 5 | B6: Context switching | C6: What the OS saves/restores; why it's expensive (cache and TLB effects); voluntary vs involuntary switches | D6: Learn (45): switch sequence + cost analysis. Quiz (15): explain the cost in your own words; voluntary vs involuntary example. | E6: Not started | F6: 1 | G6: Can explain step-by-step what happens on a context switch and why too-frequent switching hurts throughput. | H6: Follow-up to scheduling questions: 'what does a context switch cost?' | I6: 4
A7: 6 | B7: Inter-process communication (IPC) | C7: Why processes need to talk; pipes, message queues, shared memory; trade-offs | D7: Learn (45): 3 mechanisms + trade-off table. Quiz (15): pick the right IPC for 3 scenarios. | E7: Not started | F7: 1 | G7: Can name 3 IPC mechanisms, explain when each fits, and answer 'how do two browser tabs share data?' | H7: Shows systems thinking; asked in backend interviews. | I7: 4
A8: 7 | B8: CPU scheduling: goals and metrics | C8: Throughput, turnaround time, waiting time, response time; fairness vs efficiency trade-offs | D8: Learn (45): the 4 metrics + trade-off examples. Quiz (15): define each metric; explain why no scheduler optimizes all four. | E8: Not started | F8: 1 | G8: Can define all 4 metrics and explain with an example why optimizing one hurts another. | H8: Sets up every scheduling-algorithm question. | I8: 5
A9: 8 | B9: Scheduling algorithms I: FCFS, SJF, Round Robin | C9: FCFS + convoy effect; SJF/SRTF (optimal but needs future knowledge); Round Robin + quantum trade-off | D9: Learn (40): algorithms + worked examples. Drill (20): compute waiting/turnaround for a 4-process set under each algorithm by hand. | E9: Not started | F9: 1 | G9: Given arrival/burst times, can compute waiting and turnaround for FCFS, SJF, RR by hand + explain the convoy effect. | H9: 'Compare FCFS vs SJF vs Round Robin' is standard. | I9: 7
A10: 9 | B10: Scheduling algorithms II: priority, starvation, real schedulers | C10: Priority scheduling + starvation; aging fix; multilevel feedback queues; how Linux CFS works (sketch) | D10: Learn (45): starvation/aging + MLFQ idea. Quiz (15): explain starvation + the aging fix; one paragraph on CFS. | E10: Not started | F10: 1 | G10: Can explain starvation and the aging fix, and describe how a real scheduler adapts to process behavior. | H10: 'What scheduler does Linux use?' separates memorized answers from understanding. | I10: 8
A11: 10 | B11: Race conditions | C11: Shared state; non-atomic operations; the lost-update (counter++) interleaving; why testing can't catch races | D11: Learn (45): counter++ interleaving walkthrough. Quiz (15): construct your own interleaving that breaks a 'check-then-act'. | E11: Not started | F11: 1 | G11: Can walk through the lost-update example and explain why races are timing-dependent and hard to reproduce. | H11: Foundation of all synchronization questions. | I11: 3
A12: 11 | B12: Critical sections and mutual exclusion | C12: The 3 requirements (mutual exclusion, progress, bounded waiting); why a simple flag fails | D12: Learn (45): requirements + broken-flag demo. Quiz (15): state the 3 requirements; break the naive flag solution. | E12: Not started | F12: 1 | G12: Can state the 3 requirements and prove (by interleaving) why a simple boolean flag fails. | H12: Shows you understand the problem before the solutions. | I12: 10
A13: 12 | B13: Locks and mutexes | C13: Spinlock vs blocking mutex; when spinning wins; priority inversion (Mars Pathfinder) and priority inheritance | D13: Learn (45): spin vs block + Pathfinder story. Quiz (15): 'spinlock vs mutex — when each?' + retell the inversion story. | E13: Not started | F13: 1 | G13: Can explain the spin-vs-block trade-off and tell the priority-inversion story with its fix. | H13: 'Spinlock vs mutex' is a classic; the story makes it stick. | I13: 11
A14: 13 | B14: Semaphores and the producer-consumer problem | C14: Counting vs binary semaphores; wait/signal semantics; bounded-buffer solution; why wait() order matters | D14: Day 1 — Learn (45): semaphore semantics + full producer-consumer walkthrough. Quiz (15): 5 questions. Day 2 — Drill (60): write producer-consumer from scratch, then deliberately swap the wait() order and explain the deadlock. | E14: Not started | F14: 2 | G14: Can write producer-consumer with semaphores on a whiteboard and explain why swapping wait() order deadlocks. | H14: The most-asked synchronization coding question. | I14: 12
... A28: 27 | B28: OS capstone: the full story | C28: 'What happens when you double-click an app': loader, PCB, scheduling, syscalls, virtual memory, file I/O; timed mock interview | D28: Day 1 — Build (60): write and rehearse the 5-minute narration. Day 2 — Mock (60): 10 follow-up questions, timed, then fix gaps. | E28: Not started | F28: 2 | G28: Can deliver a coherent 5-minute narration touching loader, PCB, scheduling, VM, and files + survive 10 follow-ups. | H28: The ultimate OS interview answer in one story. | I28: 16,21,24,26

Sheet DBMS
A1: # | B1: Topic | C1: Subtopics / What to learn | D1: Day activity | E1: Status | F1: Est. days | G1: Done when | H1: Why it matters | I1: Depends on
A2: 1 | B2: What is a database and a DBMS | C2: Files vs DBMS; what a DBMS guarantees (persistence, concurrency, recovery); DBMS examples | D2: Learn (45): 4 problems with app-data-in-files. Quiz (15): 'why not just JSON files?' | E2: Done | F2: 1 | G2: Can list 4 file-storage problems and what a DBMS adds for each. | H2: 'Why not just use files?' opens DB discussions.
A3: 2 | B3: Data models and schemas | C3: Relational, document, graph models; schema vs data; physical/logical independence (idea) | D3: Learn (45): model zoo + schema-vs-data. Quiz (15): classify 3 use cases to a model. | E3: Not started | F3: 1 | G3: Can explain schema vs data and pick a model for 3 scenarios. | H3: Vocabulary for every data discussion. | I3: 1
A4: 3 | B4: ER modeling | C4: Entities, attributes (key, derived, multivalued), relationships, cardinality, weak entities | D4: Learn (40): ER notation. Drill (20): draw ER for a college (students/courses/enrollments). | E4: Not started | F4: 1 | G4: Can draw a correct ER diagram with cardinalities for a small domain. | H4: Design questions start with modeling. | I4: 2
A5: 4 | B5: From ER to tables | C5: Entity to table; 1:N via foreign keys; M:N via junction tables; weak entity mapping | D5: Learn (30): mapping rules. Drill (30): convert your ER diagram to tables. | E5: Not started | F5: 1 | G5: Can convert any ER diagram to tables, including M:N junction tables. | H5: 'How do you model many-to-many?' | I5: 3
A6: 5 | B6: The relational model and keys | C6: Relations, tuples, domains; primary/foreign/candidate/super keys; constraints (NOT NULL, UNIQUE, CHECK, DEFAULT) | D6: Learn (45): key taxonomy. Quiz (15): pick the right PK for 3 scenarios; define each key. | E6: Not started | F6: 1 | G6: Can define each key type and choose PKs with reasons. | H6: Key terminology is interview vocabulary. | I6: 4
A7: 6 | B7: SQL I: SELECT, WHERE, NULL | C7: SELECT/WHERE/ORDER BY/LIMIT/DISTINCT; NULL semantics (NULL != NULL, 3-valued logic) | D7: Learn (40): query basics + NULL traps. Drill (20): 10 queries incl. NULL edge cases. | E7: Not started | F7: 1 | G7: Can write 10/10 basic SELECTs and explain why `WHERE x != NULL` returns nothing. | H7: NULL handling is the #1 SQL gotcha. | I7: 5
A8: 7 | B8: SQL II: aggregation | C8: COUNT/SUM/AVG/MIN/MAX; GROUP BY; HAVING vs WHERE; GROUP BY pitfalls | D8: Learn (40): aggregation + HAVING. Drill (20): 6 grouped queries. | E8: Not started | F8: 1 | G8: Can explain WHERE vs HAVING with an example and write correct grouped queries. | H8: GROUP BY/HAVING in every SQL round. | I8: 6
A9: 8 | B9: SQL III: JOINs, deep | C9: Inner, left, right, full outer, cross, self joins; Venn diagrams; row-count reasoning | D9: Day 1 — Learn (45): all join types + diagrams. Quiz (15). Day 2 — Drill (60): 12 join queries incl. self-join and full-outer on small tables; predict row counts first. | E9: Not started | F9: 2 | G9: Can write every join type from memory and predict result row counts on small tables. | H9: JOINs are 80% of SQL interviews. | I9: 7
A10: 9 | B10: SQL IV: subqueries | C10: Scalar, IN, EXISTS; correlated subqueries; EXISTS vs IN (NULL trap) | D10: Learn (40): subquery forms. Drill (20): rewrite JOIN as subquery and back. | E10: Not started | F10: 1 | G10: Can rewrite JOIN as subquery and vice versa; knows when EXISTS beats IN. | H10: 'EXISTS vs IN' is a classic. | I10: 8
A11: 10 | B11: SQL V: window functions and CTEs | C11: ROW_NUMBER/RANK/DENSE_RANK; PARTITION BY; running totals; LAG/LEAD; WITH clauses; views | D11: Day 1 — Learn (45): window anatomy + top-N-per-group. Quiz (15). Day 2 — Drill (60): running totals, LAG deltas, CTE refactor of a nested query. | E11: Not started | F11: 2 | G11: Can solve top-N-per-group and running-total problems with window functions. | H11: Window functions = 'advanced SQL' signal. | I11: 9
A12: 11 | B12: DDL, DML, TCL | C12: CREATE/ALTER/DROP; INSERT/UPDATE/DELETE; COMMIT/ROLLBACK/SAVEPOINT | D12: Learn (40): the three families. Quiz (20): what ROLLBACK undoes; write a savepoint scenario. | E12: Not started | F12: 1 | G12: Can explain the three families and what ROLLBACK undoes. | H12: Sets up transactions. | I12: 10
A13: 12 | B13: Normalization: anomalies and 1NF | C13: Insertion/update/deletion anomalies; atomic values; 1NF | D13: Learn (40): anomaly stories. Drill (20): spot anomalies; convert to 1NF. | E13: Not started | F13: 1 | G13: Can spot anomalies in an unnormalized table and fix to 1NF. | H13: 'Why normalize?' needs the anomaly story. | I13: 5
A14: 13 | B14: 2NF and 3NF | C14: Functional dependencies; partial dependency (2NF); transitive dependency (3NF); worked decompositions | D14: Learn (40): FD notation + examples. Drill (20): given FDs, decompose to 3NF. | E14: Not started | F14: 1 | G14: Given a table + FDs, can find violations and decompose to 3NF. | H14: 'What is 3NF?' asked verbatim. | I14: 12
... A25: 24 | B25: DBMS capstone | C25: Design a 3NF schema for a mini-app; 10 interview SQL queries (joins + windows); defend normalization and index choices; timed mock | D25: Day 1 — Build (60): schema + queries on paper. Day 2 — Mock (60): defend every choice; 10 follow-ups. | E25: Not started | F25: 2 | G25: Can whiteboard a 3NF schema, write joins/window queries live, and defend each decision. | H25: Simulates a real DB interview round. | I25: 10,17,22,23

Sheet Networks
A1: # | B1: Topic | C1: Subtopics / What to learn | D1: Day activity | E1: Status | F1: Est. days | G1: Done when | H1: Why it matters | I1: Depends on
A2: 1 | B2: What is a network | C2: Packets and protocols; latency vs bandwidth vs throughput | D2: Learn (45): the three metrics + examples. Quiz (15): 'why doesn't high bandwidth mean low latency?' | E2: Not started | F2: 1 | G2: Can define all three metrics and explain the distinction with an example. | H2: 'Latency vs bandwidth' is asked constantly.
A3: 2 | B3: OSI vs TCP/IP | C3: 7 layers in order, each layer's one-line job; TCP/IP 4-layer map; encapsulation | D3: Learn (45): layer-by-layer. Quiz (15): recite layers in order + each job. | E3: Not started | F3: 1 | G3: Can list all 7 OSI layers in order with each layer's job. | H3: Asked verbatim. | I3: 1
A4: 3 | B4: IPv4 addressing | C4: Dotted decimal; private vs public ranges; subnet mask idea (preview) | D4: Learn (40): ranges. Drill (20): classify 10 addresses. | E4: Not started | F4: 1 | G4: Can classify any IPv4 address as private/public from memory. | H4: Private-range knowledge is assumed. | I4: 2
A5: 4 | B5: Subnetting and CIDR | C5: Masks, CIDR notation; computing network/broadcast/usable hosts; subnet planning | D5: Day 1 — Learn (45): notation + method. Quiz (15). Day 2 — Drill (60): 10 hand computations incl. /26 and /22. | E5: Not started | F5: 2 | G5: Given 192.168.1.0/26, can compute subnets, hosts, broadcast by hand. | H5: The standard networking numerical question. | I5: 3
A6: 5 | B6: DHCP and NAT | C6: DHCP DORA; NAT and port mapping; why NAT exists (IPv4 exhaustion) | D6: Learn (45): DORA + NAT table. Quiz (15): trace a laptop getting online. | E6: Not started | F6: 1 | G6: Can trace DHCP and explain NAT's role. | H6: 'How does your laptop get an IP?' | I6: 4
A7: 6 | B7: Routing basics | C7: Routers, routing tables, hops; longest-prefix match; default route; static vs dynamic (sketch) | D7: Learn (45): table-lookup walkthrough. Quiz (15): longest-prefix on 3 entries. | E7: Not started | F7: 1 | G7: Can explain longest-prefix match and what a default route does. | H7: 'What does a router actually do?' | I7: 5
A8: 7 | B8: TCP vs UDP | C8: Reliability vs speed; headers compared; when to use which | D8: Learn (40): trade-off table. Quiz (20): pick TCP/UDP for 4 apps + justify. | E8: Not started | F8: 1 | G8: Can choose correctly for 4 applications with reasons. | H8: Top-3 networking question. | I8: 2
A9: 8 | B9: TCP reliability | C9: Sequence numbers, ACKs, retransmission timers; cumulative ACKs | D9: Learn (45): lost-packet walkthrough. Quiz (15): narrate recovery. | E9: Not started | F9: 1 | G9: Can walk through a lost packet and TCP's recovery. | H9: 'How does TCP guarantee delivery?' | I9: 7
A10: 9 | B10: Handshake, teardown, SYN flood | C10: 3-way handshake with flags; 4-way close; SYN flood attack and SYN cookies | D10: Learn (45): flag-by-flag diagram. Quiz (15): draw handshake blank; explain the attack. | E10: Not started | F10: 1 | G10: Can draw the 3-way handshake and explain SYN flood + cookies. | H10: Asked verbatim, attack included. | I10: 8
A11: 10 | B11: Flow and congestion control | C11: Sliding window; slow start; AIMD (additive increase, multiplicative decrease) | D11: Learn (45): why TCP starts slow. Quiz (15): sketch the sawtooth; explain AIMD fairness. | E11: Not started | F11: 1 | G11: Can explain slow start and the AIMD sawtooth. | H11: Depth beyond the handshake. | I11: 9
A12: 11 | B12: DNS, deep | C12: Resolution chain (stub to recursive to root to TLD to authoritative); A/AAAA/CNAME/MX/TXT; caching and TTL | D12: Learn (45): full chain trace. Quiz (15): 'what does each record type do?' | E12: Not started | F12: 1 | G12: Can trace a DNS lookup step by step and explain each record type. | H12: 'What happens when you type a URL' starts here. | I12: 6
A13: 12 | B13: HTTP I: messages, methods, status codes | C13: Request/response anatomy; GET/POST/PUT/PATCH/DELETE; status classes with examples | D13: Learn (40): anatomy + codes. Drill (20): write a raw HTTP request by hand. | E13: Not started | F13: 1 | G13: Can hand-write a valid HTTP request and explain each status class. | H13: Every web interview assumes this. | I13: 11
A14: 13 | B14: HTTP II: headers, cookies, sessions | C14: Common headers; cookies; session vs JWT auth flows | D14: Learn (45): login flows compared. Quiz (15): trace a cookie login. | E14: Not started | F14: 1 | G14: Can explain cookie-session vs JWT flows. | H14: Auth questions live here. | I14: 12
... A21: 20 | B21: Networks capstone: the URL story | C21: 'What happens when you type google.com': DNS to TCP to TLS to HTTP to render; tools: dig, curl -v, traceroute; timed mock | D21: Day 1 — Build (60): rehearse with real tool output. Day 2 — Mock (60): 10 follow-ups. | E21: Not started | F21: 2 | G21: Can give the 5-minute full story using real dig/curl output. | H21: THE networking interview question. | I21: 11,15,19

Sheet Linux
A1: # | B1: Topic | C1: Subtopics / What to learn | D1: Day activity | E1: Status | F1: Est. days | G1: Done when | H1: Why it matters | I1: Depends on
A2: 1 | B2: What is Linux and the Unix philosophy | C2: Kernel vs distro; 'everything is a file'; why servers run Linux | D2: Learn (45): philosophy + 3 server reasons. Quiz (15): explain the philosophy in your words. | E2: Not started | F2: 1 | G2: Can explain the Unix philosophy and why it shapes the tools. | H2: Context for everything after.
A3: 2 | B3: Terminal and shell basics | C3: Terminal vs shell vs bash; pwd, ls, cd; man pages; tab completion | D3: Learn (30): navigate. Lab (30): learn an unknown command via man only. | E3: Not started | F3: 1 | G3: Can navigate anywhere and learn a new command from man unaided. | H3: Assumed from day one. | I3: 1
A4: 3 | B4: Filesystem hierarchy and file ops | C4: /, /etc, /var, /home, /tmp, /proc, /dev; touch/cat/less/head/tail; mkdir/rm/cp/mv | D4: Learn (30): where-things-live. Lab (30): 10 file ops. | E4: Not started | F4: 1 | G4: Can say what lives at 5 key paths and do 10/10 file ops. | H4: 'Where are the logs?' | I4: 2
A5: 4 | B5: Permissions: rwx, chmod, chown, sudo | C5: Reading ls -l; numeric and symbolic chmod; chown/chgrp; sudo and why not root | D5: Learn (40): decode + set. Lab (20): fix a 'permission denied' deploy. | E5: Not started | F5: 1 | G5: Can decode any permission string and set any combo both chmod ways. | H5: 'What does -rwxr-xr-- mean?' | I5: 3
A6: 5 | B6: Processes and jobs | C6: ps, top/htop; kill and signals (TERM vs KILL); &, jobs, fg/bg, nohup | D6: Learn (40): signals. Lab (20): hang a process, find it, kill it properly. | E6: Not started | F6: 1 | G6: Can kill a hung process correctly and explain signal choices. | H6: 'How do you kill a stuck process?' | I6: 3
A7: 6 | B7: Pipes and redirection | C7: |, >, >>, <, 2>, 2>&1, /dev/null | D7: Learn (30): operators. Lab (30): build 3 pipelines; silence errors properly. | E7: Not started | F7: 1 | G7: Can chain commands and explain every redirection operator. | H7: Composability interviewers expect. | I7: 5
A8: 7 | B8: Text processing: grep, sed, awk, find | C8: grep patterns; sed substitutions; awk fields; sort/uniq/wc/cut; find -name/-exec | D8: Learn (45): the toolkit. Lab (15 within the hour): top-10 IPs from a log one-liner; find-and-act. Quiz (15): predict outputs. | E8: Not started | F8: 1 | G8: Can extract top-10 IPs from a log in one line and find files by 3 criteria. | H8: 'Parse this log' is a real interview task. | I8: 6
A9: 8 | B9: Environment variables and PATH | C9: env, export; PATH resolution; .bashrc vs .profile | D9: Learn (40): PATH mechanics. Lab (20): fix 'command not found' three ways. | E9: Not started | F9: 1 | G9: Can explain and fix 'command not found'. | H9: Classic trap, asked as trivia. | I9: 2
A10: 9 | B10: Networking tools and SSH | C10: curl/wget; ping; ss vs netstat; ssh/scp; key auth and ssh-keygen | D10: Learn (30): tool tour. Lab (30): curl an API, check ports, set up key auth, scp a file. | E10: Not started | F10: 1 | G10: Can curl, inspect ports, and SSH with keys. | H10: Debugging deploys; 'how do you secure SSH?' | I10: 3
A11: 10 | B11: Packages, users, and disks | C11: apt update/install; useradd, groups, least privilege; df/du; 'disk full' diagnosis (deleted-but-open files) | D11: Learn (40): the trio. Lab (20): create a limited deploy user; diagnose fake disk-full. | E11: Not started | F11: 1 | G11: Can create a least-privilege user and diagnose disk-full. | H11: Famous production issue. | I11: 4
A12: 11 | B12: Bash scripting | C12: Shebang, variables, quoting; conditionals, loops; functions, args; exit codes; set -euo pipefail | D12: Learn (40): syntax + pitfalls. Lab (20): script with usage() and error checks. | E12: Not started | F12: 1 | G12: Can write a robust script with proper exit codes and quoting. | H12: Automation = leverage. | I12: 6
A13: 12 | B13: systemd, cron, and logs | C13: systemctl start/enable/status; writing a service unit; cron syntax; journalctl and /var/log; tail -f | D13: Learn (30): services + cron. Lab (30): service-ize an app; schedule a job; read its logs. | E13: Not started | F13: 1 | G13: Can keep an app running via systemd and find its logs. | H13: 'How do you keep an app running?' | I13: 5
A14: 13 | B14: Linux capstone: the deploy drill | C14: SSH in, deploy app, systemd service, break it, read logs, fix; timed mock | D14: Drill (45): full cycle. Break/fix (15): 2 injected failures, diagnose each. | E14: Not started | F14: 1 | G14: Can do the full deploy-and-recover cycle unaided. | H14: Proves operational readiness. | I14: 9,10,12

Sheet Frontend-TS-React
A1: # | B1: Topic | C1: Subtopics / What to learn | D1: Day activity | E1: Status | F1: Est. days | G1: Done when | H1: Why it matters | I1: Depends on
A2: 1 | B2: TypeScript setup & strict mode | C2: tsc, tsconfig, strict flags (strictNullChecks, noImplicitAny), editor integration | D2: Scaffold a TS playground repo; convert a 60-line JS utility to strict TS, fixing every error without using any | E2: Not started | F2: 1 | G2: Can explain what each strict flag catches; converts JS to strict TS cleanly | H2: Interviewers ask 'why TypeScript?' and probe strict-mode pitfalls live
A3: 2 | B3: Basic types, inference, any vs unknown vs never | C3: primitives, literal types, inference, assertions, any/unknown/never | D3: Type a utils module; write one function that must use unknown plus narrowing instead of any | E3: Not started | F3: 1 | G3: Can explain any vs unknown vs never with examples; never ships a silent any | H3: 'any vs unknown' is a classic TypeScript interview question | I3: 1
A4: 3 | B4: Interfaces, type aliases & object shapes | C4: interface vs type, optional/readonly, index signatures, extends | D4: Model a task-tracker domain (User, Task, Project with relations) | E4: Not started | F4: 2 | G4: Can defend interface-vs-type choices and model a domain cleanly | H4: Domain-modeling questions test exactly this skill | I4: 2
A5: 4 | B5: Functions & generics I | C5: signatures, overloads, generic functions, default type params | D5: Build a generic fetch wrapper and a generic filter/sort helper | E5: Not started | F5: 2 | G5: Can write generic utilities and explain overloads vs unions | H5: 'Write a generic debounce' appears in frontend rounds | I5: 3
A6: 5 | B6: Advanced generics | C6: constraints, keyof, typeof, mapped types, conditional types, infer | D6: Build a type-safe EventEmitter and a DeepPartial form-state type | E6: Not started | F6: 3 | G6: Can read and write mapped/conditional types and explain infer | H6: Library-level TS separates seniors from juniors | I6: 4
A7: 6 | B7: Unions, narrowing & utility types | C7: discriminated unions, type guards, Partial/Pick/Omit/Record/ReturnType/Awaited | D7: Model API states (idle/loading/success/error) with exhaustive switch narrowing | E7: Not started | F7: 2 | G7: Can model state with discriminated unions; uses utility types fluently | H7: State modeling is asked in almost every React interview | I7: 5
A8: 7 | B8: TypeScript with React | C8: typing props/events/refs/children, generic components, declaration files for untyped JS | D8: Build a typed component kit (Button, Input, Modal, generic Table<T>); write one .d.ts for a JS lib | E8: Not started | F8: 2 | G8: Can type any component pattern including generics and ref forwarding | H8: 'Type this component' is a live-coding staple | I8: 6
A9: 8 | B9: End-to-end type safety | C9: shared types, zod schemas, inferring TS types from zod, tRPC concept | D9: Define zod schemas for an API and derive every frontend type from them | E9: Not started | F9: 2 | G9: Can set up a zod-to-TS pipeline and explain runtime vs compile-time safety | H9: Full-stack type safety is a hot interview topic | I9: 7
A10: 9 | B10: React mental model | C10: components, JSX transform, reconciliation, virtual DOM, render vs commit | D10: Build a small app with render logging; predict re-renders, then verify | E10: Not started | F10: 1 | G10: Can explain reconciliation and why keys matter, with a demo | H10: 'How does React work under the hood?' is always asked | I10: 7
A11: 10 | B11: useState, useReducer, useRef & stale closures | C11: rules of hooks, closure traps, lazy init, ref vs state | D11: Build a stopwatch; deliberately create a stale-closure bug, then fix it | E11: Not started | F11: 2 | G11: Can spot and fix stale closures on sight | H11: Stale-closure bugs are the #1 React live-debug question | I11: 9
A12: 11 | B12: useEffect mastery | C12: dependency arrays, cleanup, race conditions, StrictMode double-invoke, effect vs event | D12: Build search-as-you-type with AbortController; fix race and infinite-loop bugs | E12: Not started | F12: 2 | G12: Can write race-free effects and explain when NOT to use an effect | H12: 'Fix this useEffect' is standard in interviews | I12: 10
A13: 12 | B13: useMemo, useCallback & memo | C13: referential equality, when memoization helps vs hurts, React profiler | D13: Profile a slow list; apply memoization; measure before/after | E13: Not started | F13: 2 | G13: Can prove with the profiler whether memoization helped; knows its costs | H13: Performance questions test judgment, not memorization | I13: 11
A14: 13 | B14: Custom hooks | C14: extracting logic, useFetch, useDebounce, useLocalStorage, hook API design | D14: Build a typed 3-hook library consumed by a demo app | E14: Not started | F14: 2 | G14: Can design reusable hooks with clean TypeScript APIs | H14: 'Build useFetch' is a canonical interview task | I14: 12
... A28: 27 | B28: Capstone III — tests, docs, launch | C28: critical-path tests, README, demo recording, retrospect | D28: Add tests, write the README, deploy, record a demo | E28: Not started | F28: 1 | G28: Live URL + README + tests; can whiteboard the architecture | H28: Shipped work with docs is interview gold | I28: 26

Sheet Backend-Node-Python
A1: # | B1: Topic | C1: Subtopics / What to learn | D1: Day activity | E1: Status | F1: Est. days | G1: Done when | H1: Why it matters | I1: Depends on
A2: 1 | B2: Node.js runtime & event loop | C2: V8, libuv, loop phases, microtasks vs macrotasks, blocking the loop | D2: Write scripts proving microtask/macrotask order; block the loop with sync crypto, then fix with worker threads | E2: Done | F2: 2 | G2: Can diagram the event loop and explain why Node is weak at CPU-bound work | H2: 'Explain the event loop' is THE Node interview question
A3: 2 | B3: Async patterns in depth | C3: callbacks, promises, async/await, Promise combinators, error propagation | D3: Rewrite a callback-hell file processor with async/await plus allSettled | E3: Not started | F3: 1 | G3: Fluent with combinators; never nests callbacks | H3: Async fluency is assumed and tested via live coding | I3: 1
A4: 3 | B4: REST API design with Express/Fastify | C4: routing, REST conventions, status codes, versioning, pagination and filtering | D4: Design and build a REST API for a resource with pagination and filters | E4: Not started | F4: 2 | G4: Can design RESTful endpoints and defend status-code choices | H4: API design rounds test exactly this | I4: 2
A5: 4 | B5: Middleware, validation & error handling | C5: middleware chain, zod/joi validation, centralized errors, async error capture | D5: Add validation, error middleware, and request logging to the API | E5: Not started | F5: 1 | G5: Can structure a maintainable Express app | H5: 'How do you structure a Node service?' | I5: 3
A6: 5 | B6: Auth I — JWT | C6: access/refresh tokens, rotation, httpOnly cookies, revocation strategies | D6: Implement JWT auth with refresh-token rotation on the API | E6: Not started | F6: 2 | G6: Can implement secure JWT auth and explain refresh trade-offs | H6: Auth implementation is a must-pass topic | I6: 4
A7: 6 | B7: Auth II — sessions & OAuth2 | C7: session stores, OAuth2 authorization-code flow, social login | D7: Add Google OAuth login to the API | E7: Not started | F7: 1 | G7: Can explain the OAuth2 flow and session-vs-JWT trade-offs | H7: 'Sessions vs JWT?' is asked constantly | I7: 5
A8: 7 | B8: Databases from Node | C8: node-postgres, connection pooling, query builders vs Prisma/Drizzle | D8: Wire the API to PostgreSQL with pooling; add one Prisma model | E8: Not started | F8: 1 | G8: Can explain pooling and choose driver vs ORM with reasons | H8: DB access patterns are core backend interviews | I8: 4
A9: 8 | B9: Hardening an API | C9: file uploads (multer), rate limiting, helmet, CORS | D9: Harden the API: uploads, rate limits, helmet, locked-down CORS | E9: Not started | F9: 1 | G9: Can security-checklist an Express API | H9: Security awareness is a differentiator | I9: 7
A10: 9 | B10: Testing Node APIs | C10: supertest/vitest, test database strategy, mocking externals | D10: Write integration tests for auth plus one resource with an isolated test DB | E10: Not started | F10: 2 | G10: Can test an API end-to-end with an isolated database | H10: Backend testing is expected at good companies | I10: 8
A11: 10 | B11: Production Node | C11: clustering, graceful shutdown, env config, structured logging with pino | D11: Production-ready the API: structured logs, graceful shutdown, Dockerfile | E11: Not started | F11: 1 | G11: Can take a Node service to production | H11: 'How do you run Node in prod?' | I11: 9
A12: 11 | B12: Streams & buffers | C12: readable/writable/transform streams, backpressure, binary data | D12: Stream-transform a large CSV without loading it into memory | E12: Not started | F12: 1 | G12: Can process large data with streams and explain backpressure | H12: Streams questions test real Node depth | I12: 2
A13: 12 | B13: API documentation with OpenAPI | C13: OpenAPI/Swagger, generating docs, contract-first thinking | D13: Document the API with Swagger UI | E13: Not started | F13: 1 | G13: Can produce living API docs from code | H13: Docs discipline is noticed in reviews | I13: 4
A14: 13 | B14: GraphQL vs REST | C14: schemas, resolvers, N+1 in GraphQL, when GraphQL wins | D14: Add one GraphQL endpoint; write a REST-vs-GraphQL trade-off note | E14: Not started | F14: 2 | G14: Can compare both with concrete trade-offs | H14: 'When would you pick GraphQL?' is common | I14: 3
A15: 14 | B15: Webhooks | C15: receiving, signature verification, idempotency, retries | D15: Build a Stripe-style webhook receiver with signature verification | E15: Not started | F15: 1 | G15: Can securely receive and process webhooks | H15: Webhooks appear in real backend tasks | I15: 5
A16: 15 | B16: Python for backend developers | C16: venv, pip, type hints, dataclasses, project layout | D16: Set up a typed Python project; port one Go/JS utility to Python | E16: Not started | F16: 1 | G16: Writes typed, clean Python confidently | H16: Python fluency unlocks the Django/Zulip world
A17: 16 | B17: Python web landscape | C17: WSGI/ASGI, Django vs Flask vs FastAPI, choosing with reasons | D17: Hello-world in all three; write a one-page comparison | E17: Not started | F17: 1 | G17: Can choose a Python framework with reasons | H17: Framework-choice reasoning is interviewed | I17: 15
A18: 17 | B18: Django I — models | C18: project layout, apps, models, fields, relationships | D18: Model a Zulip-like chat domain (users, streams, messages) in Django | E18: Not started | F18: 2 | G18: Can model a domain in the Django ORM | H18: Direct Zulip/GSoC relevance; modeling is tested | I18: 16
A19: 18 | B19: Django ORM deep | C19: querysets, select_related/prefetch_related, annotations, migrations | D19: Fix N+1 queries in the chat app; write a data migration | E19: Not started | F19: 2 | G19: Can kill N+1s and write safe migrations | H19: ORM performance questions are common | I19: 17
A20: 19 | B20: Django REST Framework | C20: serializers, viewsets, permissions, throttling, token auth | D20: Expose the chat domain as a DRF API with object-level permissions | E20: Not started | F20: 2 | G20: Can ship a DRF API with proper permissions | H20: DRF is the Django interview standard | I20: 18
A21: 20 | B21: Django admin, signals & testing | C21: admin customization, signals and their costs, pytest-django | D21: Customize the admin; test models and API endpoints | E21: Not started | F21: 1 | G21: Can use the admin productively and test Django apps | H21: Django ecosystem fluency | I21: 19
A22: 21 | B22: FastAPI | C22: Pydantic, dependency injection, async endpoints, auto-generated docs | D22: Rebuild one DRF endpoint in FastAPI; compare the two | E22: Not started | F22: 1 | G22: Can compare FastAPI vs Django with trade-offs | H22: FastAPI is the modern Python interview favorite | I22: 19
A23: 22 | B23: Python asyncio | C23: event loop, async/await, httpx, async Django/FastAPI | D23: Build a concurrent scraper with httpx and asyncio | E23: Not started | F23: 1 | G23: Can write correct async Python and explain the loop | H23: Async Python is increasingly asked | I23: 15
A24: 23 | B24: Django middleware & custom auth | C24: middleware chain, custom authentication backends, request lifecycle | D24: Write custom middleware plus a token auth backend | E24: Not started | F24: 1 | G24: Can extend Django's request pipeline | H24: Shows framework depth beyond tutorials | I24: 20
A25: 24 | B25: Zulip codebase orientation | C25: Zulip architecture (Django + Tornado), key apps, dev environment | D25: Run the Zulip dev environment; trace one API request end-to-end through the code | E25: Not started | F25: 2 | G25: Can navigate Zulip's codebase and explain a request's path | H25: Direct GSoC preparation; impresses org mentors | I25: 20
A26: 25 | B26: WebSockets & realtime | C26: ws/Socket.io, rooms, scaling realtime, SSE as alternative | D26: Add live messaging to the chat app with WebSockets | E26: Not started | F26: 2 | G26: Can build realtime features and discuss scaling | H26: Realtime questions test systems thinking | I26: 10
A27: 26 | B27: Background jobs & caching | C27: BullMQ/Celery, Redis caching patterns, idempotency, cache invalidation | D27: Add a Redis-cached endpoint and a background job worker | E27: Not started | F27: 2 | G27: Can design cache-plus-queue architecture | H27: Caching/queue design is a backend staple | I27: 25
A28: 27 | B28: Capstone — production API | C28: auth, DB, cache, jobs, tests, docs, Docker | D28: Ship a production-grade API (e.g., training-journal backend) with README | E28: Not started | F28: 2 | G28: Live API with docs; can whiteboard every decision | H28: A shipped backend is the strongest interview proof | I28: 26
A29: 28 | B29: Load test & harden | C29: k6/autocannon, finding bottlenecks, rate limits, graceful degradation | D29: Load-test the capstone API; fix the top bottleneck | E29: Not started | F29: 1 | G29: Can measure and fix performance under load | H29: 'How does it behave at 10x traffic?' | I29: 27

Sheet PostgreSQL
A1: # | B1: Topic | C1: Subtopics / What to learn | D1: Day activity | E1: Status | F1: Est. days | G1: Done when | H1: Why it matters | I1: Depends on
A2: 1 | B2: SQL refresher sprint | C2: joins, subqueries, CTEs, aggregations | D2: Run a 20-query drill on a sample database covering joins and CTEs | E2: Not started | F2: 2 | G2: Can write complex joins and CTEs fluently | H2: SQL fluency is screened in nearly every backend interview
A3: 2 | B3: Window functions deep | C3: ROW_NUMBER/RANK, running totals, LAG/LEAD, partitions | D3: Write analytics queries: leaderboards, running balances, session gaps | E3: Not started | F3: 1 | G3: Can solve ranking and running-total problems in SQL | H3: Window functions are a favorite advanced-SQL question | I3: 1
A4: 3 | B4: Schema design | C4: normalization, primary/foreign keys, constraints, enums vs lookup tables | D4: Design the full schema for the chat app; justify every decision | E4: Not started | F4: 1 | G4: Can design a normalized schema and defend it | H4: Schema design rounds are standard | I4: 1
A5: 4 | B5: Data types done right | C5: numeric vs float, text/varchar, timestamptz, jsonb intro, arrays | D5: Choose types for the chat schema; write a justification note | E5: Not started | F5: 1 | G5: Can pick correct types and explain timestamptz | H5: Type mistakes are a classic gotcha question | I5: 3
A6: 5 | B6: Indexing I — B-trees & EXPLAIN | C6: how B-tree indexes work, EXPLAIN basics, when indexes get used | D6: EXPLAIN five queries; add indexes; show before/after plans | E6: Not started | F6: 1 | G6: Can read a basic plan and add the right index | H6: 'Why is this query slow?' starts here | I6: 1
A7: 6 | B7: Indexing II — advanced | C7: composite, partial, covering (INCLUDE), GIN for jsonb and full-text | D7: Index the chat app's hot queries with composite and partial indexes | E7: Not started | F7: 2 | G7: Can choose advanced index types with reasons | H7: Index-design questions separate mid from senior | I7: 5
A8: 7 | B8: EXPLAIN ANALYZE mastery | C8: reading plans, seq vs index scans, nested loops, bitmap scans, buffers | D8: Take three slow queries and optimize each with plan evidence | E8: Not started | F8: 2 | G8: Can diagnose any slow query from its plan | H8: Plan-reading is tested in backend interviews | I8: 6
A9: 8 | B9: Transactions & ACID | C9: BEGIN/COMMIT/ROLLBACK, savepoints, atomicity guarantees | D9: Build a funds-transfer with savepoints and forced-rollback demos | E9: Not started | F9: 1 | G9: Can use transactions correctly and explain ACID | H9: Transactions are fundamental backend knowledge | I9: 3
A10: 9 | B10: Isolation levels | C10: read committed, repeatable read, serializable; dirty/non-repeatable/phantom phenomena | D10: Reproduce a phantom read in two psql sessions; fix it with isolation | E10: Not started | F10: 1 | G10: Can explain anomalies and pick the right isolation level | H10: Isolation questions are advanced-interview territory | I10: 8
A11: 10 | B11: Locking | C11: row locks, FOR UPDATE, deadlocks, advisory locks, SKIP LOCKED queues | D11: Build a job queue with FOR UPDATE SKIP LOCKED | E11: Not started | F11: 1 | G11: Can design with locks and avoid deadlocks | H11: Locking knowledge signals production experience | I11: 9
A12: 11 | B12: Constraints, triggers & DB-side logic | C12: CHECK/exclusion constraints, trigger functions, plpgsql basics, DB-vs-app logic trade-off | D12: Add a trigger-maintained counter; write the DB-vs-app trade-off note | E12: Not started | F12: 1 | G12: Can use constraints/triggers and argue where logic belongs | H12: Shows judgment beyond CRUD | I12: 8
A13: 12 | B13: jsonb in practice | C13: operators, path queries, jsonb indexing, jsonb vs columns | D13: Build a flexible metadata store on jsonb with a GIN index | E13: Not started | F13: 1 | G13: Can model semi-structured data in Postgres | H13: jsonb questions test practical Postgres | I13: 4
A14: 13 | B14: Full-text search | C14: tsvector/tsquery, ranking, trigram fuzzy search, vs Elasticsearch | D14: Add ranked full-text search over messages plus fuzzy matching | E14: Not started | F14: 1 | G14: Can ship search without leaving Postgres | H14: 'How would you add search?' | I14: 6
... A25: 24 | B25: Capstone — production schema | C25: full schema, indexes, migrations, seeds, documented decisions | D25: Design and tune the production schema for the capstone backend | E25: Not started | F25: 2 | G25: Schema + indexes + migrations reviewed and justified | H25: Ties the whole sheet into interview-ready proof | I25: 17,19

Sheet System-Design
A1: # | B1: Topic | C1: Subtopics / What to learn | D1: Day activity | E1: Status | F1: Est. days | G1: Done when | H1: Why it matters | I1: Depends on
A2: 1 | B2: How to approach a design question | C2: The 4-step framework: requirements → estimates → API/data model → deep dive. Clarifying questions that impress. | D2: Learn the framework (45 min), then whiteboard it from memory in 5 min. | E2: Not started | F2: 1 | G2: Can recite the 4 steps and ask 5+ sharp clarifying questions for any prompt. | H2: Interviewers score structure first. No framework = ramble = fail.
A3: 2 | B3: Back-of-envelope math | C3: QPS, storage, bandwidth, latency numbers. Powers of 10, per-day ↔ per-second conversions. | D3: Drill: 10 estimation questions, timed, no calculator. | E3: Not started | F3: 1 | G3: Can estimate QPS/storage/bandwidth for any prompt within 2 minutes. | H3: Every design round starts here. Wrong math = wrong architecture. | I3: 1
A4: 3 | B4: Scaling basics | C4: Vertical vs horizontal scaling. Stateless vs stateful servers. Why statelessness matters. | D4: Learn (40 min) + draw a single-server vs scaled diagram from memory. | E4: Not started | F4: 1 | G4: Can explain why stateful servers break horizontal scaling, with an example. | H4: Foundation every later topic assumes. | I4: 1
A5: 4 | B5: Load balancing | C5: Algorithms: round-robin, least-connections, consistent hashing. Health checks. L4 vs L7. | D5: Learn + quiz: which algorithm for which failure mode (5 questions). | E5: Not started | F5: 1 | G5: Can pick an LB algorithm for a scenario and justify it. | H5: Asked directly and inside every case study. | I5: 3
A6: 5 | B6: Caching deep + Redis | C6: Cache hierarchies: CDN, app cache, DB cache. Redis data structures, TTL, eviction policies (LRU/LFU), cache stampede, write-through vs write-behind. | D6: Learn + hands-on: run Redis locally, try 3 data structures, trigger an eviction. | E6: Not started | F6: 2 | G6: Can design a caching layer and name 3 failure modes with fixes. | H6: The highest-ROI backend interview topic after SQL. | I6: 4
A7: 6 | B7: Database scaling: replication | C7: Leader-follower replication, lag, read scaling, failover. (Uses your PostgreSQL knowledge.) | D7: Learn + quiz: what breaks when the leader dies? | E7: Not started | F7: 1 | G7: Can draw a replicated setup and explain lag trade-offs. | H7: Every 'design X' needs a data layer that scales. | I7: 5
A8: 7 | B8: Sharding / partitioning | C8: Shard keys, hot spots, rebalancing. Consistent hashing for data. | D8: Learn + design: shard a user table 3 ways, argue the best. | E8: Not started | F8: 2 | G8: Can choose a shard key and defend it against hot-spot questions. | H8: Separates seniors from juniors in design rounds. | I8: 6
A9: 8 | B9: Message queues | C9: Kafka/RabbitMQ basics: producers, consumers, topics, pub-sub, at-least-once delivery, backpressure. | D9: Learn + quiz: when queue vs direct call (5 scenarios). | E9: Not started | F9: 1 | G9: Can name 3 problems queues solve and 2 they create. | H9: Decoupling is a favorite interview follow-up. | I9: 4
A10: 9 | B10: CAP theorem & PACELC | C10: What CAP actually says (and the myths). PACELC: latency vs consistency when no partition. | D10: Learn + classify 4 real systems (15 min). | E10: Not started | F10: 1 | G10: Can place any system on the CAP spectrum without hand-waving. | H10: Interviewers test whether you parrot or understand. | I10: 7
A11: 10 | B11: Consistency patterns | C11: Strong vs eventual consistency. Quorums (R+W>N). Version vectors, last-write-wins dangers. | D11: Learn + quiz: pick a consistency model for 4 products. | E11: Not started | F11: 1 | G11: Can justify a consistency choice per product with trade-offs. | H11: Follow-up magnet in every data-heavy design. | I11: 9
A12: 11 | B12: Rate limiting | C12: Token bucket, leaky bucket, sliding window. Where it lives (gateway vs service). | D12: Learn + implement a token bucket in 30 lines. | E12: Not started | F12: 1 | G12: Working token-bucket implementation + can compare the 3 algorithms. | H12: Classic standalone interview question. | I12: 4
A13: 12 | B13: Case study: URL shortener | C13: Full walkthrough: requirements → estimates → API → DB → cache → scale. | D13: Whiteboard it end-to-end, timed 35 min, aloud. | E13: Not started | F13: 2 | G13: Clean 35-min walkthrough without getting stuck. | H13: The canonical first design question. | I13: 2,5,11
A14: 13 | B14: Case study: Twitter/X feed | C14: Fan-out on write vs read. Timelines, ranking basics. | D14: Whiteboard it end-to-end, timed 35 min. | E14: Not started | F14: 2 | G14: Can argue fan-out strategies with numbers. | H14: Tests scale thinking at social scale. | I14: 6,8
... A19: 18 | B19: Observability basics | C19: Logs vs metrics vs traces. What to alert on. A debugging war story structure. | D19: Learn + quiz: which signal for which incident. | E19: Not started | F19: 1 | G19: Can describe how you'd find a latency spike's cause. | H19: Ops-awareness separates hires. | I19: 17
A20: 19 | B20: LLD: OOP refresh + SOLID | C20: Classes, interfaces, the 5 SOLID principles with violations fixed. | D20: Refactor 3 SOLID violations, timed. | E20: Not started | F20: 1 | G20: Can spot and fix a SOLID violation on sight. | H20: Low-level design rounds start here.
A21: 20 | B21: LLD: design patterns | C21: Singleton, factory, observer, strategy, builder — when each fits, when each is overkill. | D21: Implement 3 patterns from scratch, no peeking. | E21: Not started | F21: 2 | G21: Can implement and justify 3 patterns cold. | H21: Pattern vocabulary interviewers expect. | I21: 19
A22: 21 | B22: LLD practice: parking lot / elevator | C22: Classic LLD prompts, done properly with extensibility. | D22: Design one fully, timed 40 min, aloud. | E22: Not started | F22: 2 | G22: Complete extensible design in 40 minutes. | H22: Direct LLD interview practice. | I22: 20
A23: 22 | B23: Mock design round 1 | C23: Full 45-min interviewer-style round: unseen prompt, interruptions, follow-ups. | D23: Timed mock with Muse as interviewer. | E23: Not started | F23: 1 | G23: Survives 45 min with structure intact. | H23: Pressure practice. | I23: 12,13,14
A24: 23 | B24: Mock design round 2 | C24: Second full round, harder prompt + deeper follow-ups. | D24: Timed mock with Muse as interviewer. | E24: Not started | F24: 1 | G24: Handles deep follow-ups without collapsing. | H24: Pressure practice. | I24: 22
A25: 24 | B25: Design sign-off | C25: Revisit weak spots from mocks. | D25: Write a one-page cheat sheet of your own. | E25: Not started | F25: 1 | G25: Cheat sheet written; can teach the framework to someone else. | H25: Teaching = never redoing. | I25: 23

Sheet Security
A1: # | B1: Topic | C1: Subtopics / What to learn | D1: Day activity | E1: Status | F1: Est. days | G1: Done when | H1: Why it matters | I1: Depends on
A2: 1 | B2: Threat-model mindset | C2: How attackers think: assets, entry points, trust boundaries. Security as a habit, not a feature. | D2: Learn (40 min) + threat-model a login page on paper. | E2: Not started | F2: 1 | G2: Can list assets and entry points for any small app. | H2: Mindset interviewers want in full-stack hires.
A3: 2 | B3: HTTPS/TLS deep | C3: Why HTTPS, handshake summary, certificates, what TLS does NOT protect. | D3: Learn + quiz: 5 questions. | E3: Not started | F3: 1 | G3: Can explain the handshake simply and name 2 TLS misconceptions. | H3: Asked more than you'd expect. | I3: 1
A4: 3 | B4: Hashing vs encryption | C4: bcrypt/argon2, salts, why MD5/SHA1 are dead for passwords. At-rest encryption basics. | D4: Learn + quiz: pick the right tool for 5 scenarios. | E4: Not started | F4: 1 | G4: Never confuses hashing with encryption again; can justify bcrypt params. | H4: Password-handling is an interview staple. | I4: 2
A5: 4 | B5: SQL injection → parameterized queries | C5: How injection works, why string-concatenated SQL dies, ORMs are not magic. | D5: Exploit a demo, then fix it. (Safe local lab.) | E5: Not started | F5: 1 | G5: Can demo the attack and the fix. | H5: Classic interview question with a live-demo answer. | I5: 3
A6: 5 | B6: XSS: stored, reflected, DOM + CSP | C6: How XSS works, escaping, Content-Security-Policy headers. | D6: Learn + find 2 XSS sinks in sample code. | E6: Not started | F6: 1 | G6: Can explain all 3 XSS types and mitigate each. | H6: Frontend-security favorite. | I6: 4
